Workbook

Sheet Data
A1: Team | B1: M | C1: W | D1: L | E1: NRR | F1: Points | G1: Metric | H1: Value | J1: Category | K1: Count | M1: Win Predictor | O1: Form (Actual) | P1: Predicted Form | Q1: Hist Win%
A2: PBKS | B2: 3 | C2: 2 | D2: 0 | E2: 0.637 | F2: 5 | G2: Avg Points/Match | H2: =AVERAGE(F2:F11) -> 2.6 | J2: Strong (≥4 pts) | K2: =COUNTIF(F2:F11,">=4") -> 4 | M2: =IF((C2/B2*100+E2)>=65,"Favourite",IF((C2/B2*100+E2)>=35,"Contender","Underdog")) -> Favourite | O2: =IF(C2/B2>=0.5,"Strong","Weak") -> Strong | P2: =O2 -> Strong | Q2: 47
A3: RCB | B3: 2 | C3: 2 | D3: 0 | E3: 2.501 | F3: 4 | G3: Max Points | H3: =MAX(F2:F11) -> 6 | J3: Mid (1-3 pts) | K3: =COUNTIFS(F2:F11,">=1",F2:F11,"<=3") -> 4 | M3: =IF((C3/B3*100+E3)>=65,"Favourite",IF((C3/B3*100+E3)>=35,"Contender","Underdog")) -> Favourite | O3: =IF(C3/B3>=0.5,"Strong","Weak") -> Strong | P3: =O3 -> Strong | Q3: 48
A4: RR | B4: 3 | C4: 3 | D4: 0 | E4: 2.233 | F4: 6 | G4: Min Points | H4: =MIN(F2:F11) -> 0 | J4: Struggling (0) | K4: =COUNTIF(F2:F11,0) -> 2 | M4: =IF((C4/B4*100+E4)>=65,"Favourite",IF((C4/B4*100+E4)>=35,"Contender","Underdog")) -> Favourite | O4: =IF(C4/B4>=0.5,"Strong","Weak") -> Strong | P4: =O4 -> Strong | Q4: 51
A5: DC | B5: 2 | C5: 2 | D5: 0 | E5: 1.17 | F5: 4 | G5: Avg NRR | H5: =AVERAGE(E2:E11) -> 0.1163 | M5: =IF((C5/B5*100+E5)>=65,"Favourite",IF((C5/B5*100+E5)>=35,"Contender","Underdog")) -> Favourite | O5: =IF(C5/B5>=0.5,"Strong","Weak") -> Strong | P5: =O5 -> Strong | Q5: 46
A6: SRH | B6: 3 | C6: 1 | D6: 2 | E6: 0.275 | F6: 2 | G6: Std Dev (Points) | H6: =STDEV(F2:F11) -> 2.0655911 | M6: =IF((C6/B6*100+E6)>=65,"Favourite",IF((C6/B6*100+E6)>=35,"Contender","Underdog")) -> Underdog | O6: =IF(C6/B6>=0.5,"Strong","Weak") -> Weak | P6: =O6 -> Weak | Q6: 49
A7: MI | B7: 3 | C7: 1 | D7: 2 | E7: -0.206 | F7: 2 | G7: Variance | H7: =VAR(F2:F11) -> 4.2666667 | M7: =IF((C7/B7*100+E7)>=65,"Favourite",IF((C7/B7*100+E7)>=35,"Contender","Underdog")) -> Underdog | O7: =IF(C7/B7>=0.5,"Strong","Weak") -> Weak | P7: =O7 -> Weak | Q7: 57
A8: LSG | B8: 2 | C8: 1 | D8: 1 | E8: -0.542 | F8: 2 | G8: Median Points | H8: =MEDIAN(F2:F11) -> 2 | M8: =IF((C8/B8*100+E8)>=65,"Favourite",IF((C8/B8*100+E8)>=35,"Contender","Underdog")) -> Contender | O8: =IF(C8/B8>=0.5,"Strong","Weak") -> Strong | P8: =O8 -> Strong | Q8: 50
A9: GT | B9: 3 | C9: 0 | D9: 3 | E9: -0.424 | F9: 0 | G9: Top-4 threshold | H9: =LARGE(F2:F11,4) -> 4 | M9: =IF((C9/B9*100+E9)>=65,"Favourite",IF((C9/B9*100+E9)>=35,"Contender","Underdog")) -> Underdog | O9: =IF(C9/B9>=0.5,"Strong","Weak") -> Weak | P9: =O9 -> Weak | Q9: 56
A10: KKR | B10: 3 | C10: 0 | D10: 2 | E10: -1.964 | F10: 1 | G10: Avg Win% | H10: =AVERAGE(Q2:Q11) -> 51.5 | M10: =IF((C10/B10*100+E10)>=65,"Favourite",IF((C10/B10*100+E10)>=35,"Contender","Underdog")) -> Underdog | O10: =IF(C10/B10>=0.5,"Strong","Weak") -> Weak | P10: =O10 -> Weak | Q10: 52
A11: CSK | B11: 3 | C11: 0 | D11: 3 | E11: -2.517 | F11: 0 | G11: Max Win% | H11: =MAX(Q2:Q11) -> 59 | M11: =IF((C11/B11*100+E11)>=65,"Favourite",IF((C11/B11*100+E11)>=35,"Contender","Underdog")) -> Underdog | O11: =IF(C11/B11>=0.5,"Strong","Weak") -> Weak | P11: =O11 -> Weak | Q11: 59
G12: Min Win% | H12: =MIN(Q2:Q11) -> 46
G14: Accuracy (IF match) | H14: 1
A16: Team | B16: Points | C16: NRR | D16: Reg Ŷ | G16: Pts(reg) | H16: NRR(reg)
A17: PBKS | B17: =F2 -> 5 | C17: =E2 -> 0.637 | D17: =SLOPE($G$17:$G$26,$H$17:$H$26)*C17+INTERCEPT($G$17:$G$26,$H$17:$H$26) -> 3.157408 | G17: 5 | H17: 0.637
A18: RCB | B18: =F3 -> 4 | C18: =E3 -> 2.501 | D18: =SLOPE($G$17:$G$26,$H$17:$H$26)*C18+INTERCEPT($G$17:$G$26,$H$17:$H$26) -> 5.152815 | G18: 4 | H18: 2.501
A19: RR | B19: =F4 -> 6 | C19: =E4 -> 2.233 | D19: =SLOPE($G$17:$G$26,$H$17:$H$26)*C19+INTERCEPT($G$17:$G$26,$H$17:$H$26) -> 4.8659217 | G19: 6 | H19: 2.233
A20: DC | B20: =F5 -> 4 | C20: =E5 -> 1.17 | D20: =SLOPE($G$17:$G$26,$H$17:$H$26)*C20+INTERCEPT($G$17:$G$26,$H$17:$H$26) -> 3.7279831 | G20: 4 | H20: 1.17
A21: SRH | B21: =F6 -> 2 | C21: =E6 -> 0.275 | D21: =SLOPE($G$17:$G$26,$H$17:$H$26)*C21+INTERCEPT($G$17:$G$26,$H$17:$H$26) -> 2.7698879 | G21: 2 | H21: 0.275
A22: MI | B22: =F7 -> 2 | C22: =E7 -> -0.206 | D22: =SLOPE($G$17:$G$26,$H$17:$H$26)*C22+INTERCEPT($G$17:$G$26,$H$17:$H$26) -> 2.2549787 | G22: 2 | H22: -0.206
A23: LSG | B23: =F8 -> 2 | C23: =E8 -> -0.542 | D23: =SLOPE($G$17:$G$26,$H$17:$H$26)*C23+INTERCEPT($G$17:$G$26,$H$17:$H$26) -> 1.8952916 | G23: 2 | H23: -0.542
A24: GT | B24: =F9 -> 0 | C24: =E9 -> -0.424 | D24: =SLOPE($G$17:$G$26,$H$17:$H$26)*C24+INTERCEPT($G$17:$G$26,$H$17:$H$26) -> 2.0216103 | G24: 0 | H24: -0.424
A25: KKR | B25: =F10 -> 1 | C25: =E10 -> -1.964 | D25: =SLOPE($G$17:$G$26,$H$17:$H$26)*C25+INTERCEPT($G$17:$G$26,$H$17:$H$26) -> 0.37304436 | G25: 1 | H25: -1.964
A26: CSK | B26: =F11 -> 0 | C26: =E11 -> -2.517 | D26: =SLOPE($G$17:$G$26,$H$17:$H$26)*C26+INTERCEPT($G$17:$G$26,$H$17:$H$26) -> -0.21894067 | G26: 0 | H26: -2.517
A29: Slope (m) | B29: Slope (m)
A30: Intercept (b) | B30: =INTERCEPT($G$17:$G$26,$H$17:$H$26) -> 2.4755012
A31: R² | B31: =CORREL($H$17:$H$26,$G$17:$G$26)^2 -> 0.70622717
A33: Team A | B33: Team B | C33: Win% A | D33: Win% B | E33: P(A wins) | F33: P(B wins) | G33: Prediction
A34: RCB | B34: CSK | C34: 48 | D34: 59 | E34: =C34/(C34+D34) -> 0.44859813 | F34: =D34/(C34+D34) -> 0.55140187 | G34: =IF(E34>F34,"RCB wins","CSK wins") -> CSK wins
A35: MI | B35: KKR | C35: 57 | D35: 52 | E35: =C35/(C35+D35) -> 0.52293578 | F35: =D35/(C35+D35) -> 0.47706422 | G35: =IF(E35>F35,"MI wins","KKR wins") -> MI wins
A36: RR | B36: DC | C36: 51 | D36: 46 | E36: =C36/(C36+D36) -> 0.5257732 | F36: =D36/(C36+D36) -> 0.4742268 | G36: =IF(E36>F36,"RR wins","DC wins") -> RR wins
A37: PBKS | B37: SRH | C37: 47 | D37: 49 | E37: =C37/(C37+D37) -> 0.48958333 | F37: =D37/(C37+D37) -> 0.51041667 | G37: =IF(E37>F37,"PBKS wins","SRH wins") -> SRH wins
A38: GT | B38: LSG | C38: 56 | D38: 50 | E38: =C38/(C38+D38) -> 0.52830189 | F38: =D38/(C38+D38) -> 0.47169811 | G38: =IF(E38>F38,"GT wins","LSG wins") -> GT wins
A39: RCB | B39: MI | C39: 48 | D39: 57 | E39: =C39/(C39+D39) -> 0.45714286 | F39: =D39/(C39+D39) -> 0.54285714 | G39: =IF(E39>F39,"RCB wins","MI wins") -> MI wins
A40: RR | B40: PBKS | C40: 51 | D40: 47 | E40: =C40/(C40+D40) -> 0.52040816 | F40: =D40/(C40+D40) -> 0.47959184 | G40: =IF(E40>F40,"RR wins","PBKS wins") -> RR wins
A41: DC | B41: KKR | C41: 46 | D41: 52 | E41: =C41/(C41+D41) -> 0.46938776 | F41: =D41/(C41+D41) -> 0.53061224 | G41: =IF(E41>F41,"DC wins","KKR wins") -> KKR wins
A42: SRH | B42: CSK | C42: 49 | D42: 59 | E42: =C42/(C42+D42) -> 0.4537037 | F42: =D42/(C42+D42) -> 0.5462963 | G42: =IF(E42>F42,"SRH wins","CSK wins") -> CSK wins
A43: GT | B43: RCB | C43: 56 | D43: 48 | E43: =C43/(C43+D43) -> 0.53846154 | F43: =D43/(C43+D43) -> 0.46153846 | G43: =IF(E43>F43,"GT wins","RCB wins") -> GT wins

Sheet Dashboard
B3: IPL — TEAM PERFORMANCE & MATCH PREDICTION DASHBOARD
B7: =COUNT(Data!B2:B11) -> 10 | E7: =SUM(Data!B2:B11)/2 -> 13.5 | H7: =AVERAGE(Data!E2:E11) -> 0.1163 | K7: =MAX(Data!F2:F11) -> 6 | N7: =STDEV(Data!F2:F11) -> 2.0655911 | Q7: =COUNTIF(Data!F2:F11,">=4") -> 4
B8: Teams Playing | E8: Matches Played | H8: Avg Rating (NRR) | K8: Top Points | N8: Std Dev (Pts) | Q8: Teams in Top 4
B11: ◈ IPL 2026 Points Table [Unit 1 – Descriptive Statistics]
B12: Team | C12: M | D12: W | E12: L | F12: NRR | G12: Points | H12: Predictor | I12: Form | J12: Win% | K12: Unit 1 – Measures of Variability | P12: Unit 2 – Classification Count
B13: PBKS | C13: =Data!B2 -> 3 | D13: =Data!C2 -> 2 | E13: =Data!D2 -> 0 | F13: =Data!E2 -> 0.637 | G13: =Data!F2 -> 5 | H13: =Data!M2 -> Favourite | I13: =Data!O2 -> Strong | J13: =Data!Q2 -> 47 | K13: Avg Points/Match | N13: =Data!H2 -> 2.6 | P13: Strong (≥4 pts) | R13: =Data!K2 -> 4
B14: RCB | C14: =Data!B3 -> 2 | D14: =Data!C3 -> 2 | E14: =Data!D3 -> 0 | F14: =Data!E3 -> 2.501 | G14: =Data!F3 -> 4 | H14: =Data!M3 -> Favourite | I14: =Data!O3 -> Strong | J14: =Data!Q3 -> 48 | K14: Max Points | N14: =Data!H3 -> 6 | P14: Mid (1-3 pts) | R14: =Data!K3 -> 4
B15: RR | C15: =Data!B4 -> 3 | D15: =Data!C4 -> 3 | E15: =Data!D4 -> 0 | F15: =Data!E4 -> 2.233 | G15: =Data!F4 -> 6 | H15: =Data!M4 -> Favourite | I15: =Data!O4 -> Strong | J15: =Data!Q4 -> 51 | K15: Min Points | N15: =Data!H4 -> 0 | P15: Struggling (0) | R15: =Data!K4 -> 2
B16: DC | C16: =Data!B5 -> 2 | D16: =Data!C5 -> 2 | E16: =Data!D5 -> 0 | F16: =Data!E5 -> 1.17 | G16: =Data!F5 -> 4 | H16: =Data!M5 -> Favourite | I16: =Data!O5 -> Strong | J16: =Data!Q5 -> 46 | K16: Avg NRR | N16: =Data!H5 -> 0.1163
B17: SRH | C17: =Data!B6 -> 3 | D17: =Data!C6 -> 1 | E17: =Data!D6 -> 2 | F17: =Data!E6 -> 0.275 | G17: =Data!F6 -> 2 | H17: =Data!M6 -> Underdog | I17: =Data!O6 -> Weak | J17: =Data!Q6 -> 49 | K17: Std Dev (Pts) | N17: =Data!H6 -> 2.0655911
B18: MI | C18: =Data!B7 -> 3 | D18: =Data!C7 -> 1 | E18: =Data!D7 -> 2 | F18: =Data!E7 -> -0.206 | G18: =Data!F7 -> 2 | H18: =Data!M7 -> Underdog | I18: =Data!O7 -> Weak | J18: =Data!Q7 -> 57 | K18: Variance | N18: =Data!H7 -> 4.2666667
B19: LSG | C19: =Data!B8 -> 2 | D19: =Data!C8 -> 1 | E19: =Data!D8 -> 1 | F19: =Data!E8 -> -0.542 | G19: =Data!F8 -> 2 | H19: =Data!M8 -> Contender | I19: =Data!O8 -> Strong | J19: =Data!Q8 -> 50 | K19: Median Points | N19: =Data!H8 -> 2
B20: GT | C20: =Data!B9 -> 3 | D20: =Data!C9 -> 0 | E20: =Data!D9 -> 3 | F20: =Data!E9 -> -0.424 | G20: =Data!F9 -> 0 | H20: =Data!M9 -> Underdog | I20: =Data!O9 -> Weak | J20: =Data!Q9 -> 56 | K20: Top-4 Threshold | N20: =Data!H9 -> 4
B21: KKR | C21: =Data!B10 -> 3 | D21: =Data!C10 -> 0 | E21: =Data!D10 -> 2 | F21: =Data!E10 -> -1.964 | G21: =Data!F10 -> 1 | H21: =Data!M10 -> Underdog | I21: =Data!O10 -> Weak | J21: =Data!Q10 -> 52 | K21: Avg Win% | N21: =Data!H10 -> 51.5
B22: CSK | C22: =Data!B11 -> 3 | D22: =Data!C11 -> 0 | E22: =Data!D11 -> 3 | F22: =Data!E11 -> -2.517 | G22: =Data!F11 -> 0 | H22: =Data!M11 -> Underdog | I22: =Data!O11 -> Weak | J22: =Data!Q11 -> 59
B24: ◈ Charts – Data Visualization [Unit 2] | K24: ◈ Regression & Cluster Analysis [Unit 3]
B25: Team | C25: Points | E25: Category | F25: Count | H25: Team | I25: Points | J25: Reg Ŷ | L25: Team A | M25: Team B | N25: P(A wins) | O25: P(B wins) | P25: Winner
B26: PBKS | C26: =Data!F2 -> 5 | E26: Strong (≥4 pts) | F26: =Data!K2 -> 4 | H26: PBKS | I26: =Data!F2 -> 5 | J26: =SLOPE(Data!$G$17:$G$26,Data!$H$17:$H$26)*Data!E2+INTERCEPT(Data!$G$17:$G$26,Data!$H$17:$H$26) -> 3.157408 | L26: RCB | M26: CSK | N26: =Data!E34 -> 0.44859813 | O26: =Data!F34 -> 0.55140187 | P26: =Data!G34 -> CSK wins
B27: RCB | C27: =Data!F3 -> 4 | E27: Mid (1-3 pts) | F27: =Data!K3 -> 4 | H27: RCB | I27: =Data!F3 -> 4 | J27: =SLOPE(Data!$G$17:$G$26,Data!$H$17:$H$26)*Data!E3+INTERCEPT(Data!$G$17:$G$26,Data!$H$17:$H$26) -> 5.152815 | L27: MI | M27: KKR | N27: =Data!E35 -> 0.52293578 | O27: =Data!F35 -> 0.47706422 | P27: =Data!G35 -> MI wins
B28: RR | C28: =Data!F4 -> 6 | E28: Struggling (0) | F28: =Data!K4 -> 2 | H28: RR | I28: =Data!F4 -> 6 | J28: =SLOPE(Data!$G$17:$G$26,Data!$H$17:$H$26)*Data!E4+INTERCEPT(Data!$G$17:$G$26,Data!$H$17:$H$26) -> 4.8659217 | L28: RR | M28: DC | N28: =Data!E36 -> 0.5257732 | O28: =Data!F36 -> 0.4742268 | P28: =Data!G36 -> RR wins
B29: DC | C29: =Data!F5 -> 4 | H29: DC | I29: =Data!F5 -> 4 | J29: =SLOPE(Data!$G$17:$G$26,Data!$H$17:$H$26)*Data!E5+INTERCEPT(Data!$G$17:$G$26,Data!$H$17:$H$26) -> 3.7279831 | L29: PBKS | M29: SRH | N29: =Data!E37 -> 0.48958333 | O29: =Data!F37 -> 0.51041667 | P29: =Data!G37 -> SRH wins
B30: SRH | C30: =Data!F6 -> 2 | H30: SRH | I30: =Data!F6 -> 2 | J30: =SLOPE(Data!$G$17:$G$26,Data!$H$17:$H$26)*Data!E6+INTERCEPT(Data!$G$17:$G$26,Data!$H$17:$H$26) -> 2.7698879 | L30: GT | M30: LSG | N30: =Data!E38 -> 0.52830189 | O30: =Data!F38 -> 0.47169811 | P30: =Data!G38 -> GT wins
B31: MI | C31: =Data!F7 -> 2 | H31: MI | I31: =Data!F7 -> 2 | J31: =SLOPE(Data!$G$17:$G$26,Data!$H$17:$H$26)*Data!E7+INTERCEPT(Data!$G$17:$G$26,Data!$H$17:$H$26) -> 2.2549787 | L31: RCB | M31: MI | N31: =Data!E39 -> 0.45714286 | O31: =Data!F39 -> 0.54285714 | P31: =Data!G39 -> MI wins
B32: LSG | C32: =Data!F8 -> 2 | H32: LSG | I32: =Data!F8 -> 2 | J32: =SLOPE(Data!$G$17:$G$26,Data!$H$17:$H$26)*Data!E8+INTERCEPT(Data!$G$17:$G$26,Data!$H$17:$H$26) -> 1.8952916 | L32: RR | M32: PBKS | N32: =Data!E40 -> 0.52040816 | O32: =Data!F40 -> 0.47959184 | P32: =Data!G40 -> RR wins
B33: GT | C33: =Data!F9 -> 0 | H33: GT | I33: =Data!F9 -> 0 | J33: =SLOPE(Data!$G$17:$G$26,Data!$H$17:$H$26)*Data!E9+INTERCEPT(Data!$G$17:$G$26,Data!$H$17:$H$26) -> 2.0216103 | L33: DC | M33: KKR | N33: =Data!E41 -> 0.46938776 | O33: =Data!F41 -> 0.53061224 | P33: =Data!G41 -> KKR wins
B34: KKR | C34: =Data!F10 -> 1 | H34: KKR | I34: =Data!F10 -> 1 | J34: =SLOPE(Data!$G$17:$G$26,Data!$H$17:$H$26)*Data!E10+INTERCEPT(Data!$G$17:$G$26,Data!$H$17:$H$26) -> 0.37304436 | L34: SRH | M34: CSK | N34: =Data!E42 -> 0.4537037 | O34: =Data!F42 -> 0.5462963 | P34: =Data!G42 -> CSK wins
B35: CSK | C35: =Data!F11 -> 0 | H35: CSK | I35: =Data!F11 -> 0 | J35: =SLOPE(Data!$G$17:$G$26,Data!$H$17:$H$26)*Data!E11+INTERCEPT(Data!$G$17:$G$26,Data!$H$17:$H$26) -> -0.21894067 | L35: GT | M35: RCB | N35: =Data!E43 -> 0.53846154 | O35: =Data!F43 -> 0.46153846 | P35: =Data!G43 -> GT wins
B39: ◈ Match-by-Match Win Prediction [Unit 4 & 5 – Predictive Modelling & Decision Analysis]
B40: Team A | D40: Team B | F40: P(A wins) | H40: P(B wins) | J40: Prediction | M40: Predictor Class | P40: Cluster A | R40: Cluster B
B41: RCB | D41: CSK | F41: =Data!E34 -> 0.44859813 | H41: =Data!F34 -> 0.55140187 | J41: =Data!G34 -> CSK wins | M41: =IF(Data!E34>0.6,"Strong Favourite",IF(Data!E34>0.5,"Slight Favourite","Too Close")) -> Too Close | P41: =IF(Data!Q2>=55,"High Win%",IF(Data!Q2>=49,"Mid Win%","Low Win%")) -> Low Win% | R41: =IF(Data!Q11>=55,"High Win%",IF(Data!Q11>=49,"Mid Win%","Low Win%")) -> High Win%
B42: MI | D42: KKR | F42: =Data!E35 -> 0.52293578 | H42: =Data!F35 -> 0.47706422 | J42: =Data!G35 -> MI wins | M42: =IF(Data!E35>0.6,"Strong Favourite",IF(Data!E35>0.5,"Slight Favourite","Too Close")) -> Slight Favourite | P42: =IF(Data!Q3>=55,"High Win%",IF(Data!Q3>=49,"Mid Win%","Low Win%")) -> Low Win% | R42: =IF(Data!Q10>=55,"High Win%",IF(Data!Q10>=49,"Mid Win%","Low Win%")) -> Mid Win%
B43: RR | D43: DC | F43: =Data!E36 -> 0.5257732 | H43: =Data!F36 -> 0.4742268 | J43: =Data!G36 -> RR wins | M43: =IF(Data!E36>0.6,"Strong Favourite",IF(Data!E36>0.5,"Slight Favourite","Too Close")) -> Slight Favourite | P43: =IF(Data!Q4>=55,"High Win%",IF(Data!Q4>=49,"Mid Win%","Low Win%")) -> Mid Win% | R43: =IF(Data!Q5>=55,"High Win%",IF(Data!Q5>=49,"Mid Win%","Low Win%")) -> Low Win%
B44: PBKS | D44: SRH | F44: =Data!E37 -> 0.48958333 | H44: =Data!F37 -> 0.51041667 | J44: =Data!G37 -> SRH wins | M44: =IF(Data!E37>0.6,"Strong Favourite",IF(Data!E37>0.5,"Slight Favourite","Too Close")) -> Too Close | P44: =IF(Data!Q5>=55,"High Win%",IF(Data!Q5>=49,"Mid Win%","Low Win%")) -> Low Win% | R44: =IF(Data!Q6>=55,"High Win%",IF(Data!Q6>=49,"Mid Win%","Low Win%")) -> Mid Win%
B45: GT | D45: LSG | F45: =Data!E38 -> 0.52830189 | H45: =Data!F38 -> 0.47169811 | J45: =Data!G38 -> GT wins | M45: =IF(Data!E38>0.6,"Strong Favourite",IF(Data!E38>0.5,"Slight Favourite","Too Close")) -> Slight Favourite | P45: =IF(Data!Q6>=55,"High Win%",IF(Data!Q6>=49,"Mid Win%","Low Win%")) -> Mid Win% | R45: =IF(Data!Q8>=55,"High Win%",IF(Data!Q8>=49,"Mid Win%","Low Win%")) -> Mid Win%
B46: RCB | D46: MI | F46: =Data!E39 -> 0.45714286 | H46: =Data!F39 -> 0.54285714 | J46: =Data!G39 -> MI wins | M46: =IF(Data!E39>0.6,"Strong Favourite",IF(Data!E39>0.5,"Slight Favourite","Too Close")) -> Too Close | P46: =IF(Data!Q7>=55,"High Win%",IF(Data!Q7>=49,"Mid Win%","Low Win%")) -> High Win% | R46: =IF(Data!Q7>=55,"High Win%",IF(Data!Q7>=49,"Mid Win%","Low Win%")) -> High Win%
B47: RR | D47: PBKS | F47: =Data!E40 -> 0.52040816 | H47: =Data!F40 -> 0.47959184 | J47: =Data!G40 -> RR wins | M47: =IF(Data!E40>0.6,"Strong Favourite",IF(Data!E40>0.5,"Slight Favourite","Too Close")) -> Slight Favourite | P47: =IF(Data!Q8>=55,"High Win%",IF(Data!Q8>=49,"Mid Win%","Low Win%")) -> Mid Win% | R47: =IF(Data!Q2>=55,"High Win%",IF(Data!Q2>=49,"Mid Win%","Low Win%")) -> Low Win%
B48: DC | D48: KKR | F48: =Data!E41 -> 0.46938776 | H48: =Data!F41 -> 0.53061224 | J48: =Data!G41 -> KKR wins | M48: =IF(Data!E41>0.6,"Strong Favourite",IF(Data!E41>0.5,"Slight Favourite","Too Close")) -> Too Close | P48: =IF(Data!Q9>=55,"High Win%",IF(Data!Q9>=49,"Mid Win%","Low Win%")) -> High Win% | R48: =IF(Data!Q10>=55,"High Win%",IF(Data!Q10>=49,"Mid Win%","Low Win%")) -> Mid Win%
B49: SRH | D49: CSK | F49: =Data!E42 -> 0.4537037 | H49: =Data!F42 -> 0.5462963 | J49: =Data!G42 -> CSK wins | M49: =IF(Data!E42>0.6,"Strong Favourite",IF(Data!E42>0.5,"Slight Favourite","Too Close")) -> Too Close | P49: =IF(Data!Q10>=55,"High Win%",IF(Data!Q10>=49,"Mid Win%","Low Win%")) -> Mid Win% | R49: =IF(Data!Q11>=55,"High Win%",IF(Data!Q11>=49,"Mid Win%","Low Win%")) -> High Win%
B50: GT | D50: RCB | F50: =Data!E43 -> 0.53846154 | H50: =Data!F43 -> 0.46153846 | J50: =Data!G43 -> GT wins | M50: =IF(Data!E43>0.6,"Strong Favourite",IF(Data!E43>0.5,"Slight Favourite","Too Close")) -> Slight Favourite | P50: =IF(Data!Q11>=55,"High Win%",IF(Data!Q11>=49,"Mid Win%","Low Win%")) -> High Win% | R50: =IF(Data!Q3>=55,"High Win%",IF(Data!Q3>=49,"Mid Win%","Low Win%")) -> Low Win%
B52: ◈ Summary KPIs [Unit 1 – Descriptive Statistics]
...

Sheet Description
B1: Student Name: Neha Penumetcha
B2: Roll Number: 2023001342
B3: IPL 2026 — Team Performance & Win Prediction Dashboard
B5: Objective
B6: The main objective of this project is to analyse IPL 2026 team performance data using Microsoft Excel. This dashboard helps understand team strengths, predict match outcomes, and apply statistical techniques to make data-driven decisions about which teams are most likely to win against each other.
B8: Dataset Description
B9: The dataset used in this project consists of IPL team data, including:
B10: • Team Name (10 IPL franchises)
B11: • Matches Played (M)
B12: • Wins (W) and Losses (L)
B13: • Net Run Rate (NRR) — runs scored per over minus runs conceded per over
B14: • Points (2 per win, 1 per no-result, 0 per loss)
... B70: This dashboard provides a complete data-driven analysis of IPL 2026. Using descriptive statistics (Unit 1), data visualisation (Unit 2), regression and clustering (Unit 3), predictive modelling (Unit 4), and decision analysis (Unit 5), we can identify which teams are performing well and predict match outcomes with probability estimates. As of Match 13, RR (6 pts, NRR +2.233) and RCB (4 pts, NRR +2.501) are the strongest title contenders, while CSK and GT need urgent wins to stay in playoff contention.
